<?xml version="1.0" encoding="utf-8"?>
<!-- =================================================================================== -->
<!-- |    This document was autogenerated by xacro from elerobot.urdf.xacro            | -->
<!-- |    EDITING THIS FILE BY HAND IS NOT RECOMMENDED                                 | -->
<!-- =================================================================================== -->
<robot name="elerobot">
  <!-- xacro color -->
  <material name="black">
    <color rgba="0.0 0.0 0.0 1.0"/>
  </material>
  <material name="blue">
    <color rgba="0.0 0.0 0.8 1.0"/>
  </material>
  <material name="green">
    <color rgba="0.0 0.8 0.0 1.0"/>
  </material>
  <material name="grey">
    <color rgba="0.2 0.2 0.2 1.0"/>
  </material>
  <material name="orange">
    <color rgba="1.0 0.423529411765 0.0392156862745 1.0"/>
  </material>
  <material name="brown">
    <color rgba="0.870588235294 0.811764705882 0.764705882353 1.0"/>
  </material>
  <material name="red">
    <color rgba="0.8 0.0 0.0 1.0"/>
  </material>
  <material name="white">
    <color rgba="1.0 1.0 1.0 1.0"/>
  </material>
  <!-- MACRO: transmission of the joint-->
<![CDATA[ 
  Arm_Part: Actuator, Joint, etc
  Effort ${Arm_Part} Interface - for commanding effort-based joints. 
  Velocity ${Arm_Part} Interface - for commanding velocity-based joints.
  Position ${Arm_Part} Interface - for commanding position-based joints.
  ]]>  <!-- LINK DESCRIPTION -->
  <!-- Gazebo requires a joint to a link called "world" for statically mounted robots -->
  <link name="world"/>
  <joint name="world_joint" type="fixed">
    <origin rpy="0.0 0.0 0.0" xyz="0.005 0.0 0.0"/>
    <parent link="world"/>
    <child link="elerobot_link0"/>
  </joint>
  <!-- link0 -->
  <link name="elerobot_link0">
    <visual>
      <origin rpy="-1.57079632675 0.0 0.0" xyz="-0.06 -0.06 0.053"/>
      <geometry>
        <mesh filename="package://elerobot_description/mesh/ERP03D_LINK0.STL" scale="0.001 0.001 0.001"/>
      </geometry>
      <material name="white"/>
    </visual>
    <collision>
      <origin rpy="-1.57079632675 0.0 0.0" xyz="-0.06 -0.06 0.053"/>
      <geometry>
        <mesh filename="package://elerobot_description/mesh/ERP03D_LINK0.STL" scale="0.001 0.001 0.001"/>
      </geometry>
      <material name="white"/>
    </collision>
    <inertial>
      <origin rpy="0.0 0.0 0.0" xyz="-0.0008 0.0091 0.0"/>
      <mass value="1.171"/>
      <inertia ixx="0.0017" ixy="0.0000" ixz="0.0000" iyy="0.0028" iyz="0.0000" izz="0.0017"/>
    </inertial>
  </link>
  <!-- link1 -->
  <link name="elerobot_link1">
    <visual>
      <origin rpy="0.0 0.0 0.0" xyz="-0.0528 -0.0528 -0.072"/>
      <geometry>
        <mesh filename="package://elerobot_description/mesh/ERP03D_LINK1.STL" scale="0.001 0.001 0.001"/>
      </geometry>
      <material name="white"/>
    </visual>
    <collision>
      <origin rpy="0.0 0.0 0.0" xyz="-0.0528 -0.0528 -0.072"/>
      <geometry>
        <mesh filename="package://elerobot_description/mesh/ERP03D_LINK1.STL" scale="0.001 0.001 0.001"/>
      </geometry>
      <material name="white"/>
    </collision>
    <inertial>
      <origin rpy="0.0 0.0 0.0" xyz="0.0 0.0032 0.0615"/>
      <mass value="2.488"/>
      <inertia ixx="0.0156" ixy="0.0000" ixz="0.0000" iyy="0.0154" iyz="0.0004" izz="0.0034"/>
    </inertial>
  </link>
  <!-- link2 -->
  <link name="elerobot_link2">
    <visual>
      <origin rpy="-1.57079632675 0.0 0.0" xyz="-0.054 -0.053 0.15"/>
      <geometry>
        <mesh filename="package://elerobot_description/mesh/ERP03D_LINK2.STL" scale="0.001 0.001 0.001"/>
      </geometry>
      <material name="white"/>
    </visual>
    <collision>
      <origin rpy="-1.57079632675 0.0 0.0" xyz="-0.054 -0.053 0.15"/>
      <geometry>
        <mesh filename="package://elerobot_description/mesh/ERP03D_LINK2.STL" scale="0.001 0.001 0.001"/>
      </geometry>
      <material name="white"/>
    </collision>
    <inertial>
      <origin rpy="0.0 0.0 0.0" xyz="0.0 -0.0049 0.0"/>
      <mass value="6.628"/>
      <inertia ixx="0.0137" ixy="0.0000" ixz="0.0000" iyy="0.0940" iyz="0.0000" izz="0.0997"/>
    </inertial>
  </link>
  <!-- link3 -->
  <link name="elerobot_link3">
    <visual>
      <origin rpy="-1.57079632675 0.0 3.1415926535" xyz="0.2815 0.078 0.017"/>
      <geometry>
        <mesh filename="package://elerobot_description/mesh/ERP03D_LINK3.STL" scale="0.001 0.001 0.001"/>
      </geometry>
      <material name="white"/>
    </visual>
    <collision>
      <origin rpy="-1.57079632675 0.0 3.1415926535" xyz="0.2815 0.078 0.017"/>
      <geometry>
        <mesh filename="package://elerobot_description/mesh/ERP03D_LINK3.STL" scale="0.001 0.001 0.001"/>
      </geometry>
      <material name="white"/>
    </collision>
    <inertial>
      <origin rpy="0.0 0.0 0.0" xyz="0.0052 0.0037 0.0"/>
      <mass value="3.88"/>
      <inertia ixx="0.0049" ixy="-0.0001" ixz="0.0000" iyy="0.0446" iyz="0.0000" izz="0.0456"/>
    </inertial>
  </link>
  <!-- link4 -->
  <link name="elerobot_link4">
    <visual>
      <origin rpy="-1.57079632675 0.0 0.0" xyz="-0.0772 -0.055 0.043"/>
      <geometry>
        <mesh filename="package://elerobot_description/mesh/ERP03D_LINK4.STL" scale="0.001 0.001 0.001"/>
      </geometry>
      <material name="white"/>
    </visual>
    <collision>
      <origin rpy="-1.57079632675 0.0 0.0" xyz="-0.0772 -0.055 0.043"/>
      <geometry>
        <mesh filename="package://elerobot_description/mesh/ERP03D_LINK4.STL" scale="0.001 0.001 0.001"/>
      </geometry>
      <material name="white"/>
    </collision>
    <inertial>
      <origin rpy="0.0 0.0 0.0" xyz="0.0 0.0 0.05"/>
      <mass value="1.42"/>
      <inertia ixx="0.01" ixy="0.0" ixz="0.0000" iyy="0.01" iyz="0.0" izz="0.0"/>
    </inertial>
  </link>
  <!-- link5 -->
  <link name="elerobot_link5">
    <visual>
      <origin rpy="-1.57079632675 0.0 3.1415926535" xyz="0.0745 0.0605 0.046"/>
      <geometry>
        <mesh filename="package://elerobot_description/mesh/ERP03D_LINK5.STL" scale="0.001 0.001 0.001"/>
      </geometry>
      <material name="white"/>
    </visual>
    <collision>
      <origin rpy="-1.57079632675 0.0 3.1415926535" xyz="0.0745 0.0605 0.046"/>
      <geometry>
        <mesh filename="package://elerobot_description/mesh/ERP03D_LINK5.STL" scale="0.001 0.001 0.001"/>
      </geometry>
      <material name="white"/>
    </collision>
    <inertial>
      <origin rpy="0.0 0.0 0.0" xyz="0.0 0.0023 0.0506"/>
      <mass value="1.417"/>
      <inertia ixx="0.0059" ixy="0.0" ixz="0.0000" iyy="0.0059" iyz="0.0002" izz="0.0014"/>
    </inertial>
  </link>
  <!-- link6 -->
  <link name="elerobot_link6">
    <visual>
      <origin rpy="0.0 0.0 0.0" xyz="-0.0425 -0.0425 -0.007"/>
      <geometry>
        <mesh filename="package://elerobot_description/mesh/ERP03D_LINK6.STL" scale="0.001 0.001 0.001"/>
      </geometry>
      <material name="grey"/>
    </visual>
    <collision>
      <origin rpy="0.0 0.0 0.0" xyz="-0.0425 -0.0425 -0.007"/>
      <geometry>
        <mesh filename="package://elerobot_description/mesh/ERP03D_LINK6.STL" scale="0.001 0.001 0.001"/>
      </geometry>
      <material name="grey"/>
    </collision>
    <inertial>
      <origin rpy="0.0 0.0 0.0" xyz="-0.0001 -0.00033 0.02"/>
      <mass value="0.3158"/>
      <inertia ixx="0.0003" ixy="0.0" ixz="0.0" iyy="0.0003" iyz="0.0" izz="0.0003"/>
    </inertial>
  </link>
  <link name="elerobot_link7">
    <visual>
      <origin rpy="0.0 0.0 0.0" xyz="0.0 0.0 -0.02"/>
      <geometry>
        <cylinder length="0.04" radius="0.05"/>
      </geometry>
      <material name="orange"/>
    </visual>
    <collision>
      <origin rpy="0.0 0.0 0.0" xyz="0.0 0.0 -0.02"/>
      <geometry>
        <cylinder length="0.04" radius="0.05"/>
      </geometry>
    </collision>
    <inertial>
      <origin rpy="0.0 0.0 0.0" xyz="0.0 0.0 0.0"/>
      <mass value="0.1"/>
      <inertia ixx="7.58333333333e-05" ixy="0" ixz="0" iyy="7.58333333333e-05" iyz="0" izz="0.000125"/>
    </inertial>
  </link>
  <!-- JOINT DESCRIPTION -->
  <!-- joint0 Locked -->
  <joint name="elerobot_joint0" type="revolute">
    <axis xyz="0 0 1"/>
    <origin rpy="0.0 0.0 0.0" xyz="0.0 0.0 0.115"/>
    <!-- <safety_controller k_position="50.0" k_velocity="20.0" soft_lower_limit="${-PI*0.001/180}" soft_upper_limit="${PI*0.001/180}"/> -->
    <safety_controller k_position="50.0" k_velocity="20.0" soft_lower_limit="-6.283185307" soft_upper_limit="6.283185307"/>
    <limit acceleration="15" effort="500.0" lower="-6.283185307" upper="6.283185307" velocity="3.1415926535"/>
    <parent link="elerobot_link0"/>
    <child link="elerobot_link1"/>
    <dynamics D="1" K="7000" damping="0.003" friction="0.01" mu_coulomb="0" mu_viscous="16"/>
  </joint>
  <!-- joint1 -->
  <joint name="elerobot_joint1" type="revolute">
    <axis xyz="0 0 1"/>
    <origin rpy="0.0 -1.57079632675 -1.57079632675" xyz="0.0 0.055 0.0"/>
    <safety_controller k_position="50.0" k_velocity="20.0" soft_lower_limit="-6.283185307" soft_upper_limit="6.283185307"/>
    <limit acceleration="15" effort="500.0" lower="-6.283185307" upper="6.283185307" velocity="3.1415926535"/>
    <parent link="elerobot_link1"/>
    <child link="elerobot_link2"/>
    <dynamics D="1" K="7000" damping="0.003" friction="0.01" mu_coulomb="0" mu_viscous="16"/>
  </joint>
  <!-- joint2 -->
  <joint name="elerobot_joint2" type="revolute">
    <axis xyz="0 0 1"/>
    <origin rpy="0.0 0.0 0.0" xyz="0.265 0.0 0.0"/>
    <safety_controller k_position="50.0" k_velocity="20.0" soft_lower_limit="-6.283185307" soft_upper_limit="6.283185307"/>
    <limit acceleration="15" effort="500.0" lower="-6.283185307" upper="6.283185307" velocity="3.1415926535"/>
    <parent link="elerobot_link2"/>
    <child link="elerobot_link3"/>
    <dynamics D="1" K="7000" damping="0.003" friction="0.01" mu_coulomb="0" mu_viscous="16"/>
  </joint>
  <!-- joint3 -->
  <joint name="elerobot_joint3" type="revolute">
    <axis xyz="0 0 1"/>
    <origin rpy="0.0 0.0 1.57079632675" xyz="0.24 0.0 0.06"/>
    <safety_controller k_position="50.0" k_velocity="20.0" soft_lower_limit="-6.283185307" soft_upper_limit="6.283185307"/>
    <limit acceleration="15" effort="500.0" lower="-6.283185307" upper="6.283185307" velocity="3.63028484404"/>
    <parent link="elerobot_link3"/>
    <child link="elerobot_link4"/>
    <dynamics D="1" K="7000" damping="0.003" friction="0.01" mu_coulomb="0" mu_viscous="16"/>
  </joint>
  <!-- joint4 -->
  <joint name="elerobot_joint4" type="revolute">
    <axis xyz="0 0 1"/>
    <origin rpy="0.0 -1.57079632675 1.57079632675" xyz="0.0 -0.095 0.0"/>
    <!-- <safety_controller k_position="50.0" k_velocity="20.0" soft_lower_limit="${-PI*0.001/180}" soft_upper_limit="${PI*0.001/180}"/> -->
    <safety_controller k_position="50.0" k_velocity="20.0" soft_lower_limit="-6.283185307" soft_upper_limit="6.283185307"/>
    <limit acceleration="15" effort="500.0" lower="-6.283185307" upper="6.283185307" velocity="3.63028484404"/>
    <parent link="elerobot_link4"/>
    <child link="elerobot_link5"/>
    <dynamics D="1" K="7000" damping="0.003" friction="0.01" mu_coulomb="0" mu_viscous="16"/>
  </joint>
  <!-- joint5 Locked -->
  <joint name="elerobot_joint5" type="revolute">
    <axis xyz="0 0 1"/>
    <origin rpy="-1.57079632675 0.0 0.0" xyz="0.0 0.06 0.0"/>
    <safety_controller k_position="50.0" k_velocity="20.0" soft_lower_limit="-6.283185307" soft_upper_limit="6.283185307"/>
    <limit acceleration="15" effort="500.0" lower="-6.283185307" upper="6.283185307" velocity="3.63028484404"/>
    <parent link="elerobot_link5"/>
    <child link="elerobot_link6"/>
    <dynamics D="1" K="7000" damping="0.003" friction="0.01" mu_coulomb="0" mu_viscous="16"/>
  </joint>
  <!-- joint6 -->
  <joint name="elerobot_joint6" type="fixed">
    <origin rpy="0.0 0.0 0.0" xyz="0.0 0.0 0.07"/>
    <parent link="elerobot_link6"/>
    <child link="elerobot_link7"/>
  </joint>
  <link name="vacuum_gripper_1">
    <gravity>0</gravity>
    <visual>
      <origin rpy="0 0 0" xyz="0 0 -0.0025"/>
      <geometry>
        <cylinder length="0.005" radius="0.005"/>
      </geometry>
      <material name="transparent">
        <color rgba="255 255 255 0.8"/>
      </material>
    </visual>
    <collision>
      <origin rpy="0 0 0" xyz="0 0 -0.0025"/>
      <geometry>
        <cylinder length="0.0005" radius="0.005"/>
      </geometry>
      <material name="transparent">
        <color rgba="255 255 255 0.8"/>
      </material>
    </collision>
    <inertial>
      <origin rpy="0 0 0" xyz="0.000000 0.000000 0.000000"/>
      <mass value="0.0001"/>
      <inertia ixx="1e-08" ixy="0" ixz="0" iyy="1e-08" iyz="0" izz="1e-08"/>
    </inertial>
  </link>
  <joint name="vacuum_joint_1" type="revolute">
    <axis xyz="0 0 1"/>
    <parent link="elerobot_link7"/>
    <child link="vacuum_gripper_1"/>
    <origin rpy="0 0 0" xyz="0 0 0.0025"/>
    <limit effort="50" lower="0" upper="0" velocity="50"/>
    <dynamics damping="0.0" friction="10"/>
  </joint>
<![CDATA[ 
    <joint name="${gripper_joint}" type="fixed">
      <!-- <axis xyz="0 0 1" /> -->
      <parent link="${parent_link}" />
      <child link="${vacuum_gripper}" />
      <origin rpy="0 0 0" xyz="${vacuum_x} ${vacuum_y} ${vacuum_z}" />
      <!-- <limit effort="50" velocity="50" lower="0" upper="0" /> -->
      <!-- <dynamics damping="0.0" friction="10"/> -->
    </joint>
    ]]>  <gazebo>
    <plugin filename="libgazebo_ros_vacuum_gripper.so" name="gazebo_ros_vacuum_gripper_1">
      <robotNamespace>/rokae_arm/vacuum_gripper_1</robotNamespace>
      <bodyName>vacuum_gripper_1</bodyName>
      <topicName>grasping_1</topicName>
      <maxForce>100</maxForce>
      <maxDistance>0.05</maxDistance>
      <minDistance>0.01</minDistance>
    </plugin>
  </gazebo>
  <link name="vacuum_gripper_2">
    <gravity>0</gravity>
    <visual>
      <origin rpy="0 0 0" xyz="0 0 -0.0025"/>
      <geometry>
        <cylinder length="0.005" radius="0.005"/>
      </geometry>
      <material name="transparent">
        <color rgba="255 255 255 0.8"/>
      </material>
    </visual>
    <collision>
      <origin rpy="0 0 0" xyz="0 0 -0.0025"/>
      <geometry>
        <cylinder length="0.0005" radius="0.005"/>
      </geometry>
      <material name="transparent">
        <color rgba="255 255 255 0.8"/>
      </material>
    </collision>
    <inertial>
      <origin rpy="0 0 0" xyz="0.000000 0.000000 0.000000"/>
      <mass value="0.0001"/>
      <inertia ixx="1e-08" ixy="0" ixz="0" iyy="1e-08" iyz="0" izz="1e-08"/>
    </inertial>
  </link>
  <joint name="vacuum_joint_2" type="revolute">
    <axis xyz="0 0 1"/>
    <parent link="elerobot_link7"/>
    <child link="vacuum_gripper_2"/>
    <origin rpy="0 0 0" xyz="0.015 0 0.0025"/>
    <limit effort="50" lower="0" upper="0" velocity="50"/>
    <dynamics damping="0.0" friction="10"/>
  </joint>
<![CDATA[ 
    <joint name="${gripper_joint}" type="fixed">
      <!-- <axis xyz="0 0 1" /> -->
      <parent link="${parent_link}" />
      <child link="${vacuum_gripper}" />
      <origin rpy="0 0 0" xyz="${vacuum_x} ${vacuum_y} ${vacuum_z}" />
      <!-- <limit effort="50" velocity="50" lower="0" upper="0" /> -->
      <!-- <dynamics damping="0.0" friction="10"/> -->
    </joint>
    ]]>  <gazebo>
    <plugin filename="libgazebo_ros_vacuum_gripper.so" name="gazebo_ros_vacuum_gripper_2">
      <robotNamespace>/rokae_arm/vacuum_gripper_2</robotNamespace>
      <bodyName>vacuum_gripper_2</bodyName>
      <topicName>grasping_2</topicName>
      <maxForce>100</maxForce>
      <maxDistance>0.05</maxDistance>
      <minDistance>0.01</minDistance>
    </plugin>
  </gazebo>
  <link name="vacuum_gripper_3">
    <gravity>0</gravity>
    <visual>
      <origin rpy="0 0 0" xyz="0 0 -0.0025"/>
      <geometry>
        <cylinder length="0.005" radius="0.005"/>
      </geometry>
      <material name="transparent">
        <color rgba="255 255 255 0.8"/>
      </material>
    </visual>
    <collision>
      <origin rpy="0 0 0" xyz="0 0 -0.0025"/>
      <geometry>
        <cylinder length="0.0005" radius="0.005"/>
      </geometry>
      <material name="transparent">
        <color rgba="255 255 255 0.8"/>
      </material>
    </collision>
    <inertial>
      <origin rpy="0 0 0" xyz="0.000000 0.000000 0.000000"/>
      <mass value="0.0001"/>
      <inertia ixx="1e-08" ixy="0" ixz="0" iyy="1e-08" iyz="0" izz="1e-08"/>
    </inertial>
  </link>
  <joint name="vacuum_joint_3" type="revolute">
    <axis xyz="0 0 1"/>
    <parent link="elerobot_link7"/>
    <child link="vacuum_gripper_3"/>
    <origin rpy="0 0 0" xyz="-0.015 0 0.0025"/>
    <limit effort="50" lower="0" upper="0" velocity="50"/>
    <dynamics damping="0.0" friction="10"/>
  </joint>
<![CDATA[ 
    <joint name="${gripper_joint}" type="fixed">
      <!-- <axis xyz="0 0 1" /> -->
      <parent link="${parent_link}" />
      <child link="${vacuum_gripper}" />
      <origin rpy="0 0 0" xyz="${vacuum_x} ${vacuum_y} ${vacuum_z}" />
      <!-- <limit effort="50" velocity="50" lower="0" upper="0" /> -->
      <!-- <dynamics damping="0.0" friction="10"/> -->
    </joint>
    ]]>  <gazebo>
    <plugin filename="libgazebo_ros_vacuum_gripper.so" name="gazebo_ros_vacuum_gripper_3">
      <robotNamespace>/rokae_arm/vacuum_gripper_3</robotNamespace>
      <bodyName>vacuum_gripper_3</bodyName>
      <topicName>grasping_3</topicName>
      <maxForce>100</maxForce>
      <maxDistance>0.05</maxDistance>
      <minDistance>0.01</minDistance>
    </plugin>
  </gazebo>
  <link name="vacuum_gripper_4">
    <gravity>0</gravity>
    <visual>
      <origin rpy="0 0 0" xyz="0 0 -0.0025"/>
      <geometry>
        <cylinder length="0.005" radius="0.005"/>
      </geometry>
      <material name="transparent">
        <color rgba="255 255 255 0.8"/>
      </material>
    </visual>
    <collision>
      <origin rpy="0 0 0" xyz="0 0 -0.0025"/>
      <geometry>
        <cylinder length="0.0005" radius="0.005"/>
      </geometry>
      <material name="transparent">
        <color rgba="255 255 255 0.8"/>
      </material>
    </collision>
    <inertial>
      <origin rpy="0 0 0" xyz="0.000000 0.000000 0.000000"/>
      <mass value="0.0001"/>
      <inertia ixx="1e-08" ixy="0" ixz="0" iyy="1e-08" iyz="0" izz="1e-08"/>
    </inertial>
  </link>
  <joint name="vacuum_joint_4" type="revolute">
    <axis xyz="0 0 1"/>
    <parent link="elerobot_link7"/>
    <child link="vacuum_gripper_4"/>
    <origin rpy="0 0 0" xyz="0 0.015 0.0025"/>
    <limit effort="50" lower="0" upper="0" velocity="50"/>
    <dynamics damping="0.0" friction="10"/>
  </joint>
<![CDATA[ 
    <joint name="${gripper_joint}" type="fixed">
      <!-- <axis xyz="0 0 1" /> -->
      <parent link="${parent_link}" />
      <child link="${vacuum_gripper}" />
      <origin rpy="0 0 0" xyz="${vacuum_x} ${vacuum_y} ${vacuum_z}" />
      <!-- <limit effort="50" velocity="50" lower="0" upper="0" /> -->
      <!-- <dynamics damping="0.0" friction="10"/> -->
    </joint>
    ]]>  <gazebo>
    <plugin filename="libgazebo_ros_vacuum_gripper.so" name="gazebo_ros_vacuum_gripper_4">
      <robotNamespace>/rokae_arm/vacuum_gripper_4</robotNamespace>
      <bodyName>vacuum_gripper_4</bodyName>
      <topicName>grasping_4</topicName>
      <maxForce>100</maxForce>
      <maxDistance>0.05</maxDistance>
      <minDistance>0.01</minDistance>
    </plugin>
  </gazebo>
  <link name="vacuum_gripper_5">
    <gravity>0</gravity>
    <visual>
      <origin rpy="0 0 0" xyz="0 0 -0.0025"/>
      <geometry>
        <cylinder length="0.005" radius="0.005"/>
      </geometry>
      <material name="transparent">
        <color rgba="255 255 255 0.8"/>
      </material>
    </visual>
    <collision>
      <origin rpy="0 0 0" xyz="0 0 -0.0025"/>
      <geometry>
        <cylinder length="0.0005" radius="0.005"/>
      </geometry>
      <material name="transparent">
        <color rgba="255 255 255 0.8"/>
      </material>
    </collision>
    <inertial>
      <origin rpy="0 0 0" xyz="0.000000 0.000000 0.000000"/>
      <mass value="0.0001"/>
      <inertia ixx="1e-08" ixy="0" ixz="0" iyy="1e-08" iyz="0" izz="1e-08"/>
    </inertial>
  </link>
  <joint name="vacuum_joint_5" type="revolute">
    <axis xyz="0 0 1"/>
    <parent link="elerobot_link7"/>
    <child link="vacuum_gripper_5"/>
    <origin rpy="0 0 0" xyz="0 -0.015 0.0025"/>
    <limit effort="50" lower="0" upper="0" velocity="50"/>
    <dynamics damping="0.0" friction="10"/>
  </joint>
<![CDATA[ 
    <joint name="${gripper_joint}" type="fixed">
      <!-- <axis xyz="0 0 1" /> -->
      <parent link="${parent_link}" />
      <child link="${vacuum_gripper}" />
      <origin rpy="0 0 0" xyz="${vacuum_x} ${vacuum_y} ${vacuum_z}" />
      <!-- <limit effort="50" velocity="50" lower="0" upper="0" /> -->
      <!-- <dynamics damping="0.0" friction="10"/> -->
    </joint>
    ]]>  <gazebo>
    <plugin filename="libgazebo_ros_vacuum_gripper.so" name="gazebo_ros_vacuum_gripper_5">
      <robotNamespace>/rokae_arm/vacuum_gripper_5</robotNamespace>
      <bodyName>vacuum_gripper_5</bodyName>
      <topicName>grasping_5</topicName>
      <maxForce>100</maxForce>
      <maxDistance>0.05</maxDistance>
      <minDistance>0.01</minDistance>
    </plugin>
  </gazebo>
  <link name="vacuum_gripper_6">
    <gravity>0</gravity>
    <visual>
      <origin rpy="0 0 0" xyz="0 0 -0.0025"/>
      <geometry>
        <cylinder length="0.005" radius="0.005"/>
      </geometry>
      <material name="transparent">
        <color rgba="255 255 255 0.8"/>
      </material>
    </visual>
    <collision>
      <origin rpy="0 0 0" xyz="0 0 -0.0025"/>
      <geometry>
        <cylinder length="0.0005" radius="0.005"/>
      </geometry>
      <material name="transparent">
        <color rgba="255 255 255 0.8"/>
      </material>
    </collision>
    <inertial>
      <origin rpy="0 0 0" xyz="0.000000 0.000000 0.000000"/>
      <mass value="0.0001"/>
      <inertia ixx="1e-08" ixy="0" ixz="0" iyy="1e-08" iyz="0" izz="1e-08"/>
    </inertial>
  </link>
  <joint name="vacuum_joint_6" type="revolute">
    <axis xyz="0 0 1"/>
    <parent link="elerobot_link7"/>
    <child link="vacuum_gripper_6"/>
    <origin rpy="0 0 0" xyz="0.03 0 0.0025"/>
    <limit effort="50" lower="0" upper="0" velocity="50"/>
    <dynamics damping="0.0" friction="10"/>
  </joint>
<![CDATA[ 
    <joint name="${gripper_joint}" type="fixed">
      <!-- <axis xyz="0 0 1" /> -->
      <parent link="${parent_link}" />
      <child link="${vacuum_gripper}" />
      <origin rpy="0 0 0" xyz="${vacuum_x} ${vacuum_y} ${vacuum_z}" />
      <!-- <limit effort="50" velocity="50" lower="0" upper="0" /> -->
      <!-- <dynamics damping="0.0" friction="10"/> -->
    </joint>
    ]]>  <gazebo>
    <plugin filename="libgazebo_ros_vacuum_gripper.so" name="gazebo_ros_vacuum_gripper_6">
      <robotNamespace>/rokae_arm/vacuum_gripper_6</robotNamespace>
      <bodyName>vacuum_gripper_6</bodyName>
      <topicName>grasping_6</topicName>
      <maxForce>100</maxForce>
      <maxDistance>0.05</maxDistance>
      <minDistance>0.01</minDistance>
    </plugin>
  </gazebo>
  <link name="vacuum_gripper_7">
    <gravity>0</gravity>
    <visual>
      <origin rpy="0 0 0" xyz="0 0 -0.0025"/>
      <geometry>
        <cylinder length="0.005" radius="0.005"/>
      </geometry>
      <material name="transparent">
        <color rgba="255 255 255 0.8"/>
      </material>
    </visual>
    <collision>
      <origin rpy="0 0 0" xyz="0 0 -0.0025"/>
      <geometry>
        <cylinder length="0.0005" radius="0.005"/>
      </geometry>
      <material name="transparent">
        <color rgba="255 255 255 0.8"/>
      </material>
    </collision>
    <inertial>
      <origin rpy="0 0 0" xyz="0.000000 0.000000 0.000000"/>
      <mass value="0.0001"/>
      <inertia ixx="1e-08" ixy="0" ixz="0" iyy="1e-08" iyz="0" izz="1e-08"/>
    </inertial>
  </link>
  <joint name="vacuum_joint_7" type="revolute">
    <axis xyz="0 0 1"/>
    <parent link="elerobot_link7"/>
    <child link="vacuum_gripper_7"/>
    <origin rpy="0 0 0" xyz="-0.03 0 0.0025"/>
    <limit effort="50" lower="0" upper="0" velocity="50"/>
    <dynamics damping="0.0" friction="10"/>
  </joint>
<![CDATA[ 
    <joint name="${gripper_joint}" type="fixed">
      <!-- <axis xyz="0 0 1" /> -->
      <parent link="${parent_link}" />
      <child link="${vacuum_gripper}" />
      <origin rpy="0 0 0" xyz="${vacuum_x} ${vacuum_y} ${vacuum_z}" />
      <!-- <limit effort="50" velocity="50" lower="0" upper="0" /> -->
      <!-- <dynamics damping="0.0" friction="10"/> -->
    </joint>
    ]]>  <gazebo>
    <plugin filename="libgazebo_ros_vacuum_gripper.so" name="gazebo_ros_vacuum_gripper_7">
      <robotNamespace>/rokae_arm/vacuum_gripper_7</robotNamespace>
      <bodyName>vacuum_gripper_7</bodyName>
      <topicName>grasping_7</topicName>
      <maxForce>100</maxForce>
      <maxDistance>0.05</maxDistance>
      <minDistance>0.01</minDistance>
    </plugin>
  </gazebo>
  <link name="vacuum_gripper_8">
    <gravity>0</gravity>
    <visual>
      <origin rpy="0 0 0" xyz="0 0 -0.0025"/>
      <geometry>
        <cylinder length="0.005" radius="0.005"/>
      </geometry>
      <material name="transparent">
        <color rgba="255 255 255 0.8"/>
      </material>
    </visual>
    <collision>
      <origin rpy="0 0 0" xyz="0 0 -0.0025"/>
      <geometry>
        <cylinder length="0.0005" radius="0.005"/>
      </geometry>
      <material name="transparent">
        <color rgba="255 255 255 0.8"/>
      </material>
    </collision>
    <inertial>
      <origin rpy="0 0 0" xyz="0.000000 0.000000 0.000000"/>
      <mass value="0.0001"/>
      <inertia ixx="1e-08" ixy="0" ixz="0" iyy="1e-08" iyz="0" izz="1e-08"/>
    </inertial>
  </link>
  <joint name="vacuum_joint_8" type="revolute">
    <axis xyz="0 0 1"/>
    <parent link="elerobot_link7"/>
    <child link="vacuum_gripper_8"/>
    <origin rpy="0 0 0" xyz="0 0.03 0.0025"/>
    <limit effort="50" lower="0" upper="0" velocity="50"/>
    <dynamics damping="0.0" friction="10"/>
  </joint>
<![CDATA[ 
    <joint name="${gripper_joint}" type="fixed">
      <!-- <axis xyz="0 0 1" /> -->
      <parent link="${parent_link}" />
      <child link="${vacuum_gripper}" />
      <origin rpy="0 0 0" xyz="${vacuum_x} ${vacuum_y} ${vacuum_z}" />
      <!-- <limit effort="50" velocity="50" lower="0" upper="0" /> -->
      <!-- <dynamics damping="0.0" friction="10"/> -->
    </joint>
    ]]>  <gazebo>
    <plugin filename="libgazebo_ros_vacuum_gripper.so" name="gazebo_ros_vacuum_gripper_8">
      <robotNamespace>/rokae_arm/vacuum_gripper_8</robotNamespace>
      <bodyName>vacuum_gripper_8</bodyName>
      <topicName>grasping_8</topicName>
      <maxForce>100</maxForce>
      <maxDistance>0.05</maxDistance>
      <minDistance>0.01</minDistance>
    </plugin>
  </gazebo>
  <link name="vacuum_gripper_9">
    <gravity>0</gravity>
    <visual>
      <origin rpy="0 0 0" xyz="0 0 -0.0025"/>
      <geometry>
        <cylinder length="0.005" radius="0.005"/>
      </geometry>
      <material name="transparent">
        <color rgba="255 255 255 0.8"/>
      </material>
    </visual>
    <collision>
      <origin rpy="0 0 0" xyz="0 0 -0.0025"/>
      <geometry>
        <cylinder length="0.0005" radius="0.005"/>
      </geometry>
      <material name="transparent">
        <color rgba="255 255 255 0.8"/>
      </material>
    </collision>
    <inertial>
      <origin rpy="0 0 0" xyz="0.000000 0.000000 0.000000"/>
      <mass value="0.0001"/>
      <inertia ixx="1e-08" ixy="0" ixz="0" iyy="1e-08" iyz="0" izz="1e-08"/>
    </inertial>
  </link>
  <joint name="vacuum_joint_9" type="revolute">
    <axis xyz="0 0 1"/>
    <parent link="elerobot_link7"/>
    <child link="vacuum_gripper_9"/>
    <origin rpy="0 0 0" xyz="0 -0.03 0.0025"/>
    <limit effort="50" lower="0" upper="0" velocity="50"/>
    <dynamics damping="0.0" friction="10"/>
  </joint>
<![CDATA[ 
    <joint name="${gripper_joint}" type="fixed">
      <!-- <axis xyz="0 0 1" /> -->
      <parent link="${parent_link}" />
      <child link="${vacuum_gripper}" />
      <origin rpy="0 0 0" xyz="${vacuum_x} ${vacuum_y} ${vacuum_z}" />
      <!-- <limit effort="50" velocity="50" lower="0" upper="0" /> -->
      <!-- <dynamics damping="0.0" friction="10"/> -->
    </joint>
    ]]>  <gazebo>
    <plugin filename="libgazebo_ros_vacuum_gripper.so" name="gazebo_ros_vacuum_gripper_9">
      <robotNamespace>/rokae_arm/vacuum_gripper_9</robotNamespace>
      <bodyName>vacuum_gripper_9</bodyName>
      <topicName>grasping_9</topicName>
      <maxForce>100</maxForce>
      <maxDistance>0.05</maxDistance>
      <minDistance>0.01</minDistance>
    </plugin>
  </gazebo>
  <link name="vacuum_gripper_10">
    <gravity>0</gravity>
    <visual>
      <origin rpy="0 0 0" xyz="0 0 -0.0025"/>
      <geometry>
        <cylinder length="0.005" radius="0.005"/>
      </geometry>
      <material name="transparent">
        <color rgba="255 255 255 0.8"/>
      </material>
    </visual>
    <collision>
      <origin rpy="0 0 0" xyz="0 0 -0.0025"/>
      <geometry>
        <cylinder length="0.0005" radius="0.005"/>
      </geometry>
      <material name="transparent">
        <color rgba="255 255 255 0.8"/>
      </material>
    </collision>
    <inertial>
      <origin rpy="0 0 0" xyz="0.000000 0.000000 0.000000"/>
      <mass value="0.0001"/>
      <inertia ixx="1e-08" ixy="0" ixz="0" iyy="1e-08" iyz="0" izz="1e-08"/>
    </inertial>
  </link>
  <joint name="vacuum_joint_10" type="revolute">
    <axis xyz="0 0 1"/>
    <parent link="elerobot_link7"/>
    <child link="vacuum_gripper_10"/>
    <origin rpy="0 0 0" xyz="0.02 0.02 0.0025"/>
    <limit effort="50" lower="0" upper="0" velocity="50"/>
    <dynamics damping="0.0" friction="10"/>
  </joint>
<![CDATA[ 
    <joint name="${gripper_joint}" type="fixed">
      <!-- <axis xyz="0 0 1" /> -->
      <parent link="${parent_link}" />
      <child link="${vacuum_gripper}" />
      <origin rpy="0 0 0" xyz="${vacuum_x} ${vacuum_y} ${vacuum_z}" />
      <!-- <limit effort="50" velocity="50" lower="0" upper="0" /> -->
      <!-- <dynamics damping="0.0" friction="10"/> -->
    </joint>
    ]]>  <gazebo>
    <plugin filename="libgazebo_ros_vacuum_gripper.so" name="gazebo_ros_vacuum_gripper_10">
      <robotNamespace>/rokae_arm/vacuum_gripper_10</robotNamespace>
      <bodyName>vacuum_gripper_10</bodyName>
      <topicName>grasping_10</topicName>
      <maxForce>100</maxForce>
      <maxDistance>0.05</maxDistance>
      <minDistance>0.01</minDistance>
    </plugin>
  </gazebo>
  <link name="vacuum_gripper_11">
    <gravity>0</gravity>
    <visual>
      <origin rpy="0 0 0" xyz="0 0 -0.0025"/>
      <geometry>
        <cylinder length="0.005" radius="0.005"/>
      </geometry>
      <material name="transparent">
        <color rgba="255 255 255 0.8"/>
      </material>
    </visual>
    <collision>
      <origin rpy="0 0 0" xyz="0 0 -0.0025"/>
      <geometry>
        <cylinder length="0.0005" radius="0.005"/>
      </geometry>
      <material name="transparent">
        <color rgba="255 255 255 0.8"/>
      </material>
    </collision>
    <inertial>
      <origin rpy="0 0 0" xyz="0.000000 0.000000 0.000000"/>
      <mass value="0.0001"/>
      <inertia ixx="1e-08" ixy="0" ixz="0" iyy="1e-08" iyz="0" izz="1e-08"/>
    </inertial>
  </link>
  <joint name="vacuum_joint_11" type="revolute">
    <axis xyz="0 0 1"/>
    <parent link="elerobot_link7"/>
    <child link="vacuum_gripper_11"/>
    <origin rpy="0 0 0" xyz="-0.02 -0.02 0.0025"/>
    <limit effort="50" lower="0" upper="0" velocity="50"/>
    <dynamics damping="0.0" friction="10"/>
  </joint>
<![CDATA[ 
    <joint name="${gripper_joint}" type="fixed">
      <!-- <axis xyz="0 0 1" /> -->
      <parent link="${parent_link}" />
      <child link="${vacuum_gripper}" />
      <origin rpy="0 0 0" xyz="${vacuum_x} ${vacuum_y} ${vacuum_z}" />
      <!-- <limit effort="50" velocity="50" lower="0" upper="0" /> -->
      <!-- <dynamics damping="0.0" friction="10"/> -->
    </joint>
    ]]>  <gazebo>
    <plugin filename="libgazebo_ros_vacuum_gripper.so" name="gazebo_ros_vacuum_gripper_11">
      <robotNamespace>/rokae_arm/vacuum_gripper_11</robotNamespace>
      <bodyName>vacuum_gripper_11</bodyName>
      <topicName>grasping_11</topicName>
      <maxForce>100</maxForce>
      <maxDistance>0.05</maxDistance>
      <minDistance>0.01</minDistance>
    </plugin>
  </gazebo>
  <link name="vacuum_gripper_12">
    <gravity>0</gravity>
    <visual>
      <origin rpy="0 0 0" xyz="0 0 -0.0025"/>
      <geometry>
        <cylinder length="0.005" radius="0.005"/>
      </geometry>
      <material name="transparent">
        <color rgba="255 255 255 0.8"/>
      </material>
    </visual>
    <collision>
      <origin rpy="0 0 0" xyz="0 0 -0.0025"/>
      <geometry>
        <cylinder length="0.0005" radius="0.005"/>
      </geometry>
      <material name="transparent">
        <color rgba="255 255 255 0.8"/>
      </material>
    </collision>
    <inertial>
      <origin rpy="0 0 0" xyz="0.000000 0.000000 0.000000"/>
      <mass value="0.0001"/>
      <inertia ixx="1e-08" ixy="0" ixz="0" iyy="1e-08" iyz="0" izz="1e-08"/>
    </inertial>
  </link>
  <joint name="vacuum_joint_12" type="revolute">
    <axis xyz="0 0 1"/>
    <parent link="elerobot_link7"/>
    <child link="vacuum_gripper_12"/>
    <origin rpy="0 0 0" xyz="-0.02 0.02 0.0025"/>
    <limit effort="50" lower="0" upper="0" velocity="50"/>
    <dynamics damping="0.0" friction="10"/>
  </joint>
<![CDATA[ 
    <joint name="${gripper_joint}" type="fixed">
      <!-- <axis xyz="0 0 1" /> -->
      <parent link="${parent_link}" />
      <child link="${vacuum_gripper}" />
      <origin rpy="0 0 0" xyz="${vacuum_x} ${vacuum_y} ${vacuum_z}" />
      <!-- <limit effort="50" velocity="50" lower="0" upper="0" /> -->
      <!-- <dynamics damping="0.0" friction="10"/> -->
    </joint>
    ]]>  <gazebo>
    <plugin filename="libgazebo_ros_vacuum_gripper.so" name="gazebo_ros_vacuum_gripper_12">
      <robotNamespace>/rokae_arm/vacuum_gripper_12</robotNamespace>
      <bodyName>vacuum_gripper_12</bodyName>
      <topicName>grasping_12</topicName>
      <maxForce>100</maxForce>
      <maxDistance>0.05</maxDistance>
      <minDistance>0.01</minDistance>
    </plugin>
  </gazebo>
  <link name="vacuum_gripper_13">
    <gravity>0</gravity>
    <visual>
      <origin rpy="0 0 0" xyz="0 0 -0.0025"/>
      <geometry>
        <cylinder length="0.005" radius="0.005"/>
      </geometry>
      <material name="transparent">
        <color rgba="255 255 255 0.8"/>
      </material>
    </visual>
    <collision>
      <origin rpy="0 0 0" xyz="0 0 -0.0025"/>
      <geometry>
        <cylinder length="0.0005" radius="0.005"/>
      </geometry>
      <material name="transparent">
        <color rgba="255 255 255 0.8"/>
      </material>
    </collision>
    <inertial>
      <origin rpy="0 0 0" xyz="0.000000 0.000000 0.000000"/>
      <mass value="0.0001"/>
      <inertia ixx="1e-08" ixy="0" ixz="0" iyy="1e-08" iyz="0" izz="1e-08"/>
    </inertial>
  </link>
  <joint name="vacuum_joint_13" type="revolute">
    <axis xyz="0 0 1"/>
    <parent link="elerobot_link7"/>
    <child link="vacuum_gripper_13"/>
    <origin rpy="0 0 0" xyz="0.02 -0.02 0.0025"/>
    <limit effort="50" lower="0" upper="0" velocity="50"/>
    <dynamics damping="0.0" friction="10"/>
  </joint>
<![CDATA[ 
    <joint name="${gripper_joint}" type="fixed">
      <!-- <axis xyz="0 0 1" /> -->
      <parent link="${parent_link}" />
      <child link="${vacuum_gripper}" />
      <origin rpy="0 0 0" xyz="${vacuum_x} ${vacuum_y} ${vacuum_z}" />
      <!-- <limit effort="50" velocity="50" lower="0" upper="0" /> -->
      <!-- <dynamics damping="0.0" friction="10"/> -->
    </joint>
    ]]>  <gazebo>
    <plugin filename="libgazebo_ros_vacuum_gripper.so" name="gazebo_ros_vacuum_gripper_13">
      <robotNamespace>/rokae_arm/vacuum_gripper_13</robotNamespace>
      <bodyName>vacuum_gripper_13</bodyName>
      <topicName>grasping_13</topicName>
      <maxForce>100</maxForce>
      <maxDistance>0.05</maxDistance>
      <minDistance>0.01</minDistance>
    </plugin>
  </gazebo>
  <gazebo reference="elerobot_link0">
    <material>Gazebo/White</material>
  </gazebo>
  <gazebo reference="elerobot_link1">
    <material>Gazebo/White</material>
  </gazebo>
  <gazebo reference="elerobot_link2">
    <material>Gazebo/White</material>
  </gazebo>
  <gazebo reference="elerobot_link3">
    <material>Gazebo/White</material>
  </gazebo>
  <gazebo reference="elerobot_link4">
    <material>Gazebo/White</material>
  </gazebo>
  <gazebo reference="elerobot_link5">
    <material>Gazebo/White</material>
  </gazebo>
  <gazebo reference="elerobot_link6">
    <material>Gazebo/Grey</material>
  </gazebo>
  <gazebo reference="elerobot_link7">
    <material>Gazebo/Red</material>
    <mu1>0.61</mu1>
    <mu2>0.47</mu2>
  </gazebo>
  <gazebo reference="elerobot_joint0">
    <!-- Needed for ODE to output external wrenches on joints -->
    <provideFeedback>true</provideFeedback>
  </gazebo>
  <transmission name="elerobot_joint0_transmission">
    <type>transmission_interface/SimpleTransmission</type>
    <joint name="elerobot_joint0">
      <hardwareInterface>hardware_interface/PositionJointInterface</hardwareInterface>
    </joint>
    <actuator name="elerobot_joint0_motor">
      <hardwareInterface>hardware_interface/PositionJointInterface</hardwareInterface>
      <mechanicalReduction>1</mechanicalReduction>
    </actuator>
  </transmission>
  <gazebo reference="elerobot_joint1">
    <!-- Needed for ODE to output external wrenches on joints -->
    <provideFeedback>true</provideFeedback>
  </gazebo>
  <transmission name="elerobot_joint1_transmission">
    <type>transmission_interface/SimpleTransmission</type>
    <joint name="elerobot_joint1">
      <hardwareInterface>hardware_interface/PositionJointInterface</hardwareInterface>
    </joint>
    <actuator name="elerobot_joint1_motor">
      <hardwareInterface>hardware_interface/PositionJointInterface</hardwareInterface>
      <mechanicalReduction>1</mechanicalReduction>
    </actuator>
  </transmission>
  <gazebo reference="elerobot_joint2">
    <!-- Needed for ODE to output external wrenches on joints -->
    <provideFeedback>true</provideFeedback>
  </gazebo>
  <transmission name="elerobot_joint2_transmission">
    <type>transmission_interface/SimpleTransmission</type>
    <joint name="elerobot_joint2">
      <hardwareInterface>hardware_interface/PositionJointInterface</hardwareInterface>
    </joint>
    <actuator name="elerobot_joint2_motor">
      <hardwareInterface>hardware_interface/PositionJointInterface</hardwareInterface>
      <mechanicalReduction>1</mechanicalReduction>
    </actuator>
  </transmission>
  <gazebo reference="elerobot_joint3">
    <!-- Needed for ODE to output external wrenches on joints -->
    <provideFeedback>true</provideFeedback>
  </gazebo>
  <transmission name="elerobot_joint3_transmission">
    <type>transmission_interface/SimpleTransmission</type>
    <joint name="elerobot_joint3">
      <hardwareInterface>hardware_interface/PositionJointInterface</hardwareInterface>
    </joint>
    <actuator name="elerobot_joint3_motor">
      <hardwareInterface>hardware_interface/PositionJointInterface</hardwareInterface>
      <mechanicalReduction>1</mechanicalReduction>
    </actuator>
  </transmission>
  <gazebo reference="elerobot_joint4">
    <!-- Needed for ODE to output external wrenches on joints -->
    <provideFeedback>true</provideFeedback>
  </gazebo>
  <transmission name="elerobot_joint4_transmission">
    <type>transmission_interface/SimpleTransmission</type>
    <joint name="elerobot_joint4">
      <hardwareInterface>hardware_interface/PositionJointInterface</hardwareInterface>
    </joint>
    <actuator name="elerobot_joint4_motor">
      <hardwareInterface>hardware_interface/PositionJointInterface</hardwareInterface>
      <mechanicalReduction>1</mechanicalReduction>
    </actuator>
  </transmission>
  <gazebo reference="elerobot_joint5">
    <!-- Needed for ODE to output external wrenches on joints -->
    <provideFeedback>true</provideFeedback>
  </gazebo>
  <transmission name="elerobot_joint5_transmission">
    <type>transmission_interface/SimpleTransmission</type>
    <joint name="elerobot_joint5">
      <hardwareInterface>hardware_interface/PositionJointInterface</hardwareInterface>
    </joint>
    <actuator name="elerobot_joint5_motor">
      <hardwareInterface>hardware_interface/PositionJointInterface</hardwareInterface>
      <mechanicalReduction>1</mechanicalReduction>
    </actuator>
  </transmission>
  <!-- Gazebo plugin for ROS control -->
  <gazebo>
    <!-- controller -->
    <plugin filename="libgazebo_ros_control.so" name="gazebo_ros_control">
      <robotNamespace/>
      <controlPeriod>0.001</controlPeriod>
      <robotSimType>gazebo_ros_control/DefaultRobotHWSim</robotSimType>
      <legacyModeNS>true</legacyModeNS>
    </plugin>
    <self_collide>true</self_collide>
    <plugin filename="libgazebo_ros_moveit_planning_scene.so" name="gazebo_ros_moveit_planning_scene">
      <topicName>/planning_scene</topicName>
      <sceneName>factory</sceneName>
      <robotName>/elerobot</robotName>
      <updatePeriod>0.5</updatePeriod>
    </plugin>
    <plugin filename="libGravityCompensationPlugin.so" name="gravity_compensation"/>
  </gazebo>
</robot>
